<?xml version='1.0'?>

<robot name="myrobot" xmlns:xacro="http://www.ros.org/wiki/xacro">

  <xacro:property name="cameraSize" value="0.05"/>
  <xacro:property name="cameraMass" value="0.1"/>
  <xacro:property name = "chassisMass" value = "10.00"/>
  <xacro:property name = "chassisX" value = "0.4"/>
  <xacro:property name = "chassisY" value = "0.2"/>
  <xacro:property name = "chassisZ" value = "0.1"/>

  <xacro:property name = "wheelMass" value = "5.00"/>
  <xacro:property name = "wheelR" value = "0.1"/>
  <xacro:property name = "wheelH" value = "0.05"/>

  <xacro:property name = "castorMass" value = "5.00"/>
  <xacro:property name = "castorRadius" value = "0.05"/>
  

  <!-- macro name="cylinder_inertia" params="m r h">
    <inertia  ixx="${m*(3*r*r+h*h)/12}" ixy = "0" ixz = "0"
      iyy="${m*(3*r*r+h*h)/12}" iyz = "0"
      izz="${m*r*r/2}"
    />
  </macro>
  <macro name="box_inertia" params="m x y z">
    <inertia  ixx="${m*(y*y+z*z)/12}" ixy = "0" ixz = "0"
      iyy="${m*(x*x+z*z)/12}" iyz = "0"
      izz="${m*(x*x+z*z)/12}"
    />
  </macro>
  <macro name="sphere_inertia" params="m r">
    <inertia  ixx="${2*m*r*r/5}" ixy = "0" ixz = "0"
      iyy="${2*m*r*r/5}" iyz = "0"
      izz="${2*m*r*r/5}"
    />
  </macro>  -->
  

  <xacro:include filename="$(find mybot_description)/urdf/mybot.gazebo" />
  <xacro:include filename="$(find mybot_description)/urdf/materials.xacro" />
  <xacro:include filename="$(find mybot_description)/urdf/macros.xacro" />


  <link name='chassis'>
    <pose>0 0 0.1 0 0 0</pose>

    <inertial>
      <mass value="${chassisMass}"/>
      <origin xyz="0.0 0 0.0" rpy=" 0 0 0"/>
      <!-- <inertia
          ixx="${chassisMass*(chassisY*chassisY*chassisZ*chassisZ)/12}" ixy="0" ixz="0"
          iyy="${chassisMass*(chassisX*chassisX*chassisZ*chassisZ)/12}" iyz="0"
          izz="${chassisMass*(chassisX*chassisX*chassisY*chassisY)/12}"
      /> -->
   <inertia
          ixx="0.3" ixy="0" ixz="0"
          iyy="0.3" iyz="0"
          izz="0.3"
      />

      <!-- <box_inertia 
				m="${chassisMass}" 
				x="${chassisX}" 
				y="${chassisY}" 
				z="${chassisZ}"/> -->
    </inertial>

    <collision name='collision'>
      <geometry>
        <box size=".4 .2 .1"/>
      </geometry>
    </collision>

    <visual name='chassis_visual'>
      <origin xyz="0 0 0" rpy=" 0 0 0"/>
      <geometry>
        <box size=".4 .2 .1"/>
      </geometry>
    </visual>


    <collision name='caster_collision'>
      <origin xyz="-0.15 0 -0.05" rpy=" 0 0 0"/>
      <geometry>
        <sphere radius="${castorRadius}"/>
      </geometry>
      <surface>
        <friction>
          <ode>
            <mu>0</mu>
            <mu2>0</mu2>
            <slip1>1.0</slip1>
            <slip2>1.0</slip2>
          </ode>
        </friction>
      </surface>
    </collision>

    <visual name='caster_visual'>
      <origin xyz="-0.15 0 -0.05" rpy=" 0 0 0"/>
      <geometry>
        <sphere radius="${castorRadius}"/>
      </geometry>
    </visual>

    <collision name='caster_front_collision'>
      <origin xyz="0.15 0 -0.05" rpy=" 0 0 0"/>
      <geometry>
        <sphere radius="${castorRadius}"/>
      </geometry>
      <surface>
        <friction>
          <ode>
            <mu>0</mu>
            <mu2>0</mu2>
            <slip1>1.0</slip1>
            <slip2>1.0</slip2>
          </ode>
        </friction>
      </surface>
    </collision>

    <!-- <inertial>
      <origin xyz="0 0 0" rpy="0 1.5707 1.5707"/>
      <mass value="1"/>
      <interia
        ixx=".01" ixy="0.0" ixz="0.0"
        iyy=".01" iyz="0.0"
        izz=".01"/>
    </inertial> -->

    <visual name='caster_front_visual'>
      <origin xyz="0.15 0 -0.06" rpy=" 0 0 0"/>
      <geometry>
        <sphere radius="${castorRadius}"/>
      </geometry>
    </visual>

  </link>
 <!-- <inertia  ixx="${m*(3*r*r+h*h)/12}" ixy = "0" ixz = "0"
      iyy="${m*(3*r*r+h*h)/12}" iyz = "0"
      izz="${m*r*r/2}"
    /> -->
  <link name="left_wheel">
    <!--origin xyz="0.1 0.13 0.1" rpy="0 1.5707 1.5707"/-->
    <collision name="collision_left">
      <origin xyz="0 0 0" rpy="0 1.5707 1.5707"/>
      <geometry>
        <cylinder radius="${wheelR}" length="${wheelH}"/>
      </geometry>
      <!-- <surface>
        <friction>
          <ode>
            <mu>10000.0</mu>
            <mu2>10000.0</mu2>
            <slip1>0</slip1>
            <slip2>0</slip2>
          </ode>
        </friction>
      </surface> -->
    </collision>
    <visual name="left_wheel_visual">
      <origin xyz="0 0 0" rpy="0 1.5707 1.5707"/>
      <geometry>
        <cylinder radius="${wheelR}" length="${wheelH}"/>
      </geometry>
    </visual>
     
    <inertial>
      <origin xyz="0 -0.0 0" rpy="0 1.5707 1.5707"/>
      <mass value="${wheelMass}"/>
      <inertia
        ixx="${wheelMass * (3 * wheelR * wheelR + wheelH * wheelH)/12}" ixy="0.0" ixz="0.0"
        iyy="${wheelMass * (3 * wheelR * wheelR + wheelH * wheelH)/12}" iyz="0.0"
        izz="${wheelMass * (3 * wheelR * wheelR + wheelH * wheelH)/12}"/>
    </inertial>
  </link>

  <link name="right_wheel">
    <!--origin xyz="0.1 -0.13 0.1" rpy="0 1.5707 1.5707"/-->
    <collision name="collision">
      <origin xyz="0 0 0" rpy="0 1.5707 1.5707"/>
      <geometry>
        <cylinder radius="${wheelR}" length="${wheelH}"/>
      </geometry>
      <!-- <surface>
        <friction>
          <ode>
            <mu>10000.0</mu>
            <mu2>10000.0</mu2>
            <slip1>0</slip1>
            <slip2>0</slip2>
          </ode>
        </friction>
      </surface> -->
    </collision>
    <visual name="right_wheel_visual">
      <origin xyz="0 0 0" rpy="0 1.5707 1.5707"/>
      <geometry>
       <cylinder radius="${wheelR}" length="${wheelH}"/>
      </geometry>
    </visual>
     
     <inertial>
      <origin xyz="0 -0.0 0" rpy="0 1.5707 1.5707"/>
      <mass value="${wheelMass}"/>
      <inertia
        ixx="${wheelMass * (3 * wheelR * wheelR + wheelH * wheelH)/12}" ixy="0.0" ixz="0.0"
        iyy="${wheelMass * (3 * wheelR * wheelR + wheelH * wheelH)/12}" iyz="0.0"
        izz="${wheelMass * (3 * wheelR * wheelR + wheelH * wheelH)/12}"/>
    </inertial>
  </link>


  <joint type="continuous" name="left_wheel_hinge">
    <origin xyz="0 0.15 0" rpy="0 0 0"/>
    <!--origin xyz="0.1 0.13 0" rpy="0 1.5707 1.5707"/-->
    <child link="left_wheel"/>
    <parent link="chassis"/>
    <axis xyz="0 1 0" rpy="0 0 0"/>
    <limit effort="10000" velocity="1000"/>
    <joint_properties damping="1.0" friction="1.0"/>
  </joint>

  <joint type="continuous" name="right_wheel_hinge">
    <origin xyz="0 -0.15 0" rpy="0 0 0"/>
    <!--origin xyz="0.1 -0.13 0" rpy="0 1.5707 1.5707"/-->
    <child link="right_wheel"/>
    <parent link="chassis"/>
    <axis xyz="0 1 0" rpy="0 0 0"/>
    <limit effort="10000" velocity="1000"/>
    <joint_properties damping="1.0" friction="1.0"/>
  </joint>


  <link name="camera">
    <collision>
      <origin xyz="0 0 0" rpy="0 0 0"/>
      <geometry>
        <box size="${cameraSize} ${cameraSize} ${cameraSize}"/>
      </geometry>
    </collision>

    <visual>
      <origin xyz="0 0 0" rpy="0 0 0"/>
      <geometry>
        <box size="${cameraSize} ${cameraSize} ${cameraSize}"/>
      </geometry>
      <material name="green"/>
    </visual>

    <inertial>
      <mass value="${cameraMass}" />
      <origin xyz="0 0 0" rpy="0 0 0"/>
      <box_inertia m="${cameraMass}" x="${cameraSize}" y="${cameraSize}" z="${cameraSize}" />
      <inertia ixx="1e-6" ixy="0" ixz="0" iyy="1e-6" iyz="0" izz="1e-6" />
    </inertial>
  </link>

  <joint name="camera_joint" type="fixed">
    <axis xyz="0 1 0" />
    <origin xyz=".2 0 0" rpy="0 0 0"/>
    <parent link="chassis"/>
    <child link="camera"/>
  </joint>


  <joint name="hokuyo_joint" type="fixed">
    <axis xyz="0 1 0" />
    <origin xyz=".15 0 .1" rpy="0 0 0"/>
    <parent link="chassis"/>
    <child link="hokuyo"/>
  </joint>

<!-- eagle is link planeed to introduced for getting the nearest obstacle dist to design the reward function -->
<!-- planning to introduce it later after some more reasearch in open ai Ros Gazebo libaries -->
  <!-- <joint name="eagle_joint" type="fixed">
    <axis xyz="0 1 0" />
    <origin xyz=".15 -0.5 .1" rpy="0 0 0"/>
    <parent link="chassis"/>
    <child link="eagle"/>
  </joint> -->


  <!-- Hokuyo Laser -->
  <link name="hokuyo">
    <collision>
      <origin xyz="0 0 0" rpy="0 0 0"/>
      <geometry>
    <box size="0.1 0.1 0.1"/>
      </geometry>
    </collision>

    <visual>
      <origin xyz="0 0 0" rpy="0 0 0"/>
      <geometry>
        <mesh filename="package://mybot_description/meshes/hokuyo.dae"/>
      </geometry>
    </visual>

    <inertial>
      <mass value="1e-5" />
      <origin xyz="0 0 0" rpy="0 0 0"/>
      <inertia ixx="1e-6" ixy="0" ixz="0" iyy="1e-6" iyz="0" izz="1e-6" />
    </inertial>
  </link>


<!-- <link name="eagle">
    <collision>
      <origin xyz="0 0 0" rpy="0 0 0"/>
      <geometry>
    <box size="0.1 0.1 0.1"/>
      </geometry>
    </collision>

    <visual>
      <origin xyz="0 0 0" rpy="0 0 0"/>
      <geometry>
        <mesh filename="package://mybot_description/meshes/hokuyo.dae"/>
      </geometry>
    </visual>

    <inertial>
      <mass value="1e-5" />
      <origin xyz="0 0 0" rpy="0 0 0"/>
      <inertia ixx="1e-6" ixy="0" ixz="0" iyy="1e-6" iyz="0" izz="1e-6" />
    </inertial>
  </link> -->


</robot>

